Workbook

Sheet Assumptions
A1: Nvidia (NVDA) — DCF Model Assumptions
A3: Parameter | B3: Value | C3: Units | D3: Notes
A4: Operating Assumptions
A5: Base Revenue ($mm) | B5: 130497 | C5: $mm | D5: Source: NVIDIA FY2025 10-K (Jan 2025); revenue 30.5B
A6: Revenue Growth — Yr 1 | B6: 0.6547 | C6: % | D6: stockanalysis.com
A7: Revenue Growth — Yr 2 | B7: 0.6704 | C7: % | D7: stockanalysis.com
A8: Revenue Growth — Yr 3 | B8: 0.2967 | C8: % | D8: stockanalysis.com
A9: Revenue Growth — Yr 4 | B9: 0.15 | C9: % | D9: My Assumption
A10: Revenue Growth — Yr 5 | B10: 0.11 | C10: % | D10: My Assumption
A11: Revenue Growth — Yr 6 | B11: 0.09 | C11: % | D11: Fade: Rubin ramp sustains elevated growth
A12: Revenue Growth — Yr 7 | B12: 0.08 | C12: % | D12: Fade: market penetration broadening
A13: Revenue Growth — Yr 8 | B13: 0.07 | C13: % | D13: Fade: growth normalizing toward maturity
A14: Revenue Growth — Yr 9 | B14: 0.06 | C14: % | D14: Fade: approaching steady-state
A15: Revenue Growth — Yr 10 | B15: 0.05 | C15: % | D15: Fade: normalized ~5% — closer to terminal rate
A16: Terminal Growth Rate | B16: 0.0275 | C16: % | D16: My assumption based on inevitability of long-term normalization and durable AI demand
... A30: Change in NWC as % of Rev | B30: 0.01 | C30: % | D30: Conservative NWC build assumption given rapid revenue scaling
A32: WACC Assumptions
A33: Risk-Free Rate | B33: 0.043 | C33: % | D33: 10yr US Treasury yield ~4.3% (Mar 2026)
A34: Equity Risk Premium | B34: 0.055 | C34: % | D34: Damodaran Jan 2026 ERP estimate
A35: Beta | B35: 1.22 | C35: x | D35: Source: https://www.alphaspread.com/security/nasdaq/nvda/discount-rate
A36: Cost of Equity | B36: =B33+B35*B34 -> 0.1101 | C36: % | D36: CAPM: Rf + β×ERP
A37: Pre-Tax Cost of Debt | B37: 0.035 | C37: % | D37: Source: NVIDIA FY2025; LTD .5B, investment-grade issuer
A38: Equity Weight | B38: 0.93 | C38: % | D38: Source: FY2025 D/E ratio ~0.07; near entirely equity-financed
A39: Debt Weight | B39: =1-B38 -> 0.07 | C39: % | D39: 1 - Equity Weight
A40: WACC | B40: =B38*B36+B39*B37*(1-B27) -> 0.10445345 | C40: % | D40: Kd×(1−t) blended in
A42: Terminal Value Assumptions
A43: Terminal Growth Rate | B43: 0.03 | C43: % | D43: Above-GDP given AI infrastructure secular growth trend
A44: EV/EBIT Exit Multiple | B44: 21 | C44: x | D44: Year 10 exit; 28x EBIT reflects mature AI platform premium (cross-check)
A45: Terminal Year EBITDA Mult | B45: 30 | C45: x | D45: High multiple reflecting AI leadership premium
A47: Balance Sheet Inputs
A48: Total Debt ($mm) | B48: 8462 | C48: $mm | D48: Source: NVIDIA FY2025 balance sheet; long-term debt .5B
A49: Cash & Equivalents ($mm) | B49: 15230 | C49: $mm | D49: Source: NVIDIA FY2025 balance sheet; cash & equivalents 5.2B
A50: Diluted Shares Out. (mm) | B50: 24483 | C50: mm | D50: Source: Diluted shares outstanding ~24.5B (Oct 2025 10-Q)
A51: Current Share Price | B51: 181.69 | C51: $ | D51: Source: NVDA closing price Mar 7, 2026

Sheet DCF Model
A1: Discounted Cash Flow Model
A2: All figures in unless noted | Blue = hardcoded input | Black = formula | 10-Year forecast with Gordon Growth + Exit Multiple terminal values
A4: () | B4: 2025 | C4: 2026 | D4: 2027 | E4: 2028 | F4: 2029 | G4: 2030 | H4: 2031 | I4: 2032 | J4: 2033 | K4: 2034 | L4: 2035 | M4: Terminal
A5: Revenue Build
A6: Revenue | B6: =Assumptions!B5 -> 130497 | C6: =B6*(1+C7) -> 215933.39 | D6: =C6*(1+D7) -> 360695.13 | E6: =D6*(1+E7) -> 467713.37 | F6: =E6*(1+F7) -> 537870.38 | G6: =F6*(1+G7) -> 597036.12 | H6: =G6*(1+H7) -> 650769.37 | I6: =H6*(1+I7) -> 702830.92 | J6: =I6*(1+J7) -> 752029.08 | ... L6: =K6*(1+L7) -> 837008.37
A7: Growth Rate | C7: =Assumptions!B6 -> 0.6547 | D7: =Assumptions!B7 -> 0.6704 | E7: =Assumptions!B8 -> 0.2967 | F7: =Assumptions!B9 -> 0.15 | G7: =Assumptions!B10 -> 0.11 | H7: =Assumptions!B11 -> 0.09 | I7: =Assumptions!B12 -> 0.08 | J7: =Assumptions!B13 -> 0.07 | K7: =Assumptions!B14 -> 0.06 | L7: =Assumptions!B15 -> 0.05 | M7: =Assumptions!B16 -> 0.0275
A8: Income Statement & Free Cash Flow
A9: EBIT Margin | C9: =Assumptions!B17 -> 0.621 | D9: =Assumptions!B18 -> 0.63 | E9: =Assumptions!B19 -> 0.64 | F9: =Assumptions!B20 -> 0.65 | G9: =Assumptions!B21 -> 0.65 | H9: =Assumptions!B22 -> 0.65 | I9: =Assumptions!B23 -> 0.64 | J9: =Assumptions!B24 -> 0.63 | K9: =Assumptions!B25 -> 0.62 | L9: =Assumptions!B26 -> 0.61
A10: EBIT | C10: =C6*C9 -> 134094.63 | D10: =D6*D9 -> 227237.93 | E10: =E6*E9 -> 299336.56 | F10: =F6*F9 -> 349615.75 | G10: =G6*G9 -> 388073.48 | H10: =H6*H9 -> 423000.09 | I10: =I6*I9 -> 449811.79 | J10: =J6*J9 -> 473778.32 | ... L10: =L6*L9 -> 510575.11
A11: (-) Taxes | C11: =-C10*Assumptions!B27 -> -21321.047 | D11: =-D10*Assumptions!B27 -> -36130.831 | E11: =-E10*Assumptions!B27 -> -47594.513 | F11: =-F10*Assumptions!B27 -> -55588.904 | G11: =-G10*Assumptions!B27 -> -61703.683 | H11: =-H10*Assumptions!B27 -> -67257.014 | I11: =-I10*Assumptions!B27 -> -71520.074 | J11: =-J10*Assumptions!B27 -> -75330.753 | K11: =-K10*Assumptions!B27 -> -78583.129 | L11: =-L10*Assumptions!B27 -> -81181.442
A12: NOPAT | C12: =C10+C11 -> 112773.59 | D12: =D10+D11 -> 191107.1 | E12: =E10+E11 -> 251742.05 | F12: =F10+F11 -> 294026.84 | G12: =G10+G11 -> 326369.79 | H12: =H10+H11 -> 355743.08 | I12: =I10+I11 -> 378291.71 | J12: =J10+J11 -> 398447.57 | ... L12: =L10+L11 -> 429393.66
A13: (+) D&A | C13: =C6*Assumptions!B28 -> 3023.0674 | D13: =D6*Assumptions!B28 -> 5049.7318 | E13: =E6*Assumptions!B28 -> 6547.9872 | F13: =F6*Assumptions!B28 -> 7530.1853 | G13: =G6*Assumptions!B28 -> 8358.5057 | H13: =H6*Assumptions!B28 -> 9110.7712 | I13: =I6*Assumptions!B28 -> 9839.6329 | J13: =J6*Assumptions!B28 -> 10528.407 | K13: =K6*Assumptions!B28 -> 11160.112 | L13: =L6*Assumptions!B28 -> 11718.117
A14: (-) CapEx | C14: =-C6*Assumptions!B29 -> -5398.3346 | D14: =-D6*Assumptions!B29 -> -9017.3782 | E14: =-E6*Assumptions!B29 -> -11692.834 | F14: =-F6*Assumptions!B29 -> -13446.759 | G14: =-G6*Assumptions!B29 -> -14925.903 | H14: =-H6*Assumptions!B29 -> -16269.234 | I14: =-I6*Assumptions!B29 -> -17570.773 | J14: =-J6*Assumptions!B29 -> -18800.727 | K14: =-K6*Assumptions!B29 -> -19928.771 | L14: =-L6*Assumptions!B29 -> -20925.209
A15: (-) Change in NWC | C15: =-C6*Assumptions!B30 -> -2159.3339 | D15: =-D6*Assumptions!B30 -> -3606.9513 | E15: =-E6*Assumptions!B30 -> -4677.1337 | F15: =-F6*Assumptions!B30 -> -5378.7038 | G15: =-G6*Assumptions!B30 -> -5970.3612 | H15: =-H6*Assumptions!B30 -> -6507.6937 | I15: =-I6*Assumptions!B30 -> -7028.3092 | J15: =-J6*Assumptions!B30 -> -7520.2908 | K15: =-K6*Assumptions!B30 -> -7971.5083 | L15: =-L6*Assumptions!B30 -> -8370.0837
A16: Free Cash Flow | C16: =C12+C13+C14+C15 -> 108238.98 | D16: =D12+D13+D14+D15 -> 183532.5 | E16: =E12+E13+E14+E15 -> 241920.06 | F16: =F12+F13+F14+F15 -> 282731.56 | G16: =G12+G13+G14+G15 -> 313832.04 | H16: =H12+H13+H14+H15 -> 342076.92 | I16: =I12+I13+I14+I15 -> 363532.27 | J16: =J12+J13+J14+J15 -> 382654.96 | ... L16: =L12+L13+L14+L15 -> 411816.49
A17: Discounted Cash Flow
A18: Discount Factor (WACC) | C18: =1/(1+Assumptions!B40)^1 -> 0.90542521 | D18: =1/(1+Assumptions!B40)^2 -> 0.81979482 | E18: =1/(1+Assumptions!B40)^3 -> 0.7422629 | F18: =1/(1+Assumptions!B40)^4 -> 0.67206354 | G18: =1/(1+Assumptions!B40)^5 -> 0.60850327 | H18: =1/(1+Assumptions!B40)^6 -> 0.55095421 | I18: =1/(1+Assumptions!B40)^7 -> 0.49884783 | J18: =1/(1+Assumptions!B40)^8 -> 0.4516694 | K18: =1/(1+Assumptions!B40)^9 -> 0.40895286 | L18: =1/(1+Assumptions!B40)^10 -> 0.37027623 | M18: =Assumptions!B40 -> 0.10445345
A19: PV of FCF | C19: =C16*C18 -> 98002.306 | D19: =D16*D18 -> 150458.99 | E19: =E16*E18 -> 179568.29 | F19: =F16*F18 -> 190013.58 | G19: =G16*G18 -> 190967.82 | H19: =H16*H18 -> 188468.72 | I19: =I16*I18 -> 181347.28 | J19: =J16*J18 -> 172833.54 | ... L19: =L16*L18 -> 152485.86
A20: Terminal Value
A21: Method 1 — Gordon Growth (perpetuity)
A22: Terminal FCF | M22: =L16*(1+M7)/(M18-M7) -> 5498667.6
A23: PV of Terminal Value (GG) | M23: =M22/(1+M18)^10 -> 2036025.9
A24: TV as % of Total EV (GG) | M24: =M23/L33 -> 0.54978577
A25: Method 2 — Exit Multiple (EV/EBIT)
A26: Terminal Value (Exit Multiple) | M26: =L10*Assumptions!B44 -> 10722077
A27: PV of Terminal Value (Exit) | M27: =M26/(1+Assumptions!B40)^10 -> 3970130.4
A28: TV as % of Total EV (Exit) | M28: =M27/M33 -> 0.70424695
A29: Valuation Summary
A30: Method → | L30: Gordon Growth | M30: Exit Multiple
A31: Sum of PV(FCFs) | L31: =SUM(C19:L19) -> 1667281.9 | M31: =SUM(C19:L19) -> 1667281.9
A32: PV of Terminal Value | L32: =M23 -> 2036025.9 | M32: =M27 -> 3970130.4
A33: Enterprise Value | L33: =L31+L32 -> 3703307.8 | M33: =M31+M32 -> 5637412.2
A34: (-) Total Debt | L34: =-Assumptions!B48 -> -8462 | M34: =-Assumptions!B48 -> -8462
A35: (+) Cash & Equivalents | L35: =Assumptions!B49 -> 15230 | M35: =Assumptions!B49 -> 15230
A36: Equity Value | L36: =L33+L34+L35 -> 3710075.8 | M36: =M33+M34+M35 -> 5644180.2
A37: Diluted Shares Outstanding (mm) | L37: =Assumptions!B50 -> 24483 | M37: =Assumptions!B50 -> 24483
A38: Implied Share Price | L38: =L36/L37 -> 151.53681 | M38: =M36/M37 -> 230.53467
A39: Current Share Price | L39: =Assumptions!B51 -> 181.69 | M39: =Assumptions!B51 -> 181.69
A40: Implied Upside / (Downside) | L40: =L38/L39-1 -> -0.16595953 | M40: =M38/M39-1 -> 0.26883519
A42: Footnotes
...

Sheet Sensitivity
A1: Sensitivity Analysis — Implied Share Price (Gordon Growth)
A3: Implied Share Price by WACC & Terminal Growth Rate (10-Year Model)
A4: WACC → | B4: 0.07 | C4: 0.08 | D4: 0.09 | E4: 0.1 | F4: 0.11 | G4: 0.12 | H4: TGR ↓
A5: 0.015 | B5: =('DCF Model'!L31*((0.07/Assumptions!B40))+('DCF Model'!L16*(1+0.015)/(0.07-0.015))/(1+0.07)^10-Assumptions!B48+Assumptions!B49)/Assumptions!B50 -> 203.71286 | C5: =('DCF Model'!L31*((0.08/Assumptions!B40))+('DCF Model'!L16*(1+0.015)/(0.08-0.015))/(1+0.08)^10-Assumptions!B48+Assumptions!B49)/Assumptions!B50 -> 174.09511 | D5: =('DCF Model'!L31*((0.09/Assumptions!B40))+('DCF Model'!L16*(1+0.015)/(0.09-0.015))/(1+0.09)^10-Assumptions!B48+Assumptions!B49)/Assumptions!B50 -> 155.10948 | E5: =('DCF Model'!L31*((0.1/Assumptions!B40))+('DCF Model'!L16*(1+0.015)/(0.1-0.015))/(1+0.1)^10-Assumptions!B48+Assumptions!B49)/Assumptions!B50 -> 142.91147 | F5: =('DCF Model'!L31*((0.11/Assumptions!B40))+('DCF Model'!L16*(1+0.015)/(0.11-0.015))/(1+0.11)^10-Assumptions!B48+Assumptions!B49)/Assumptions!B50 -> 135.28457 | G5: =('DCF Model'!L31*((0.12/Assumptions!B40))+('DCF Model'!L16*(1+0.015)/(0.12-0.015))/(1+0.12)^10-Assumptions!B48+Assumptions!B49)/Assumptions!B50 -> 130.86404
A6: 0.02 | B6: =('DCF Model'!L31*((0.07/Assumptions!B40))+('DCF Model'!L16*(1+0.02)/(0.07-0.02))/(1+0.07)^10-Assumptions!B48+Assumptions!B49)/Assumptions!B50 -> 220.34785 | C6: =('DCF Model'!L31*((0.08/Assumptions!B40))+('DCF Model'!L16*(1+0.02)/(0.08-0.02))/(1+0.08)^10-Assumptions!B48+Assumptions!B49)/Assumptions!B50 -> 184.88286 | D6: =('DCF Model'!L31*((0.09/Assumptions!B40))+('DCF Model'!L16*(1+0.02)/(0.09-0.02))/(1+0.09)^10-Assumptions!B48+Assumptions!B49)/Assumptions!B50 -> 162.48532 | E6: =('DCF Model'!L31*((0.1/Assumptions!B40))+('DCF Model'!L16*(1+0.02)/(0.1-0.02))/(1+0.1)^10-Assumptions!B48+Assumptions!B49)/Assumptions!B50 -> 148.15672 | F6: =('DCF Model'!L31*((0.11/Assumptions!B40))+('DCF Model'!L16*(1+0.02)/(0.11-0.02))/(1+0.11)^10-Assumptions!B48+Assumptions!B49)/Assumptions!B50 -> 139.12992 | G6: =('DCF Model'!L31*((0.12/Assumptions!B40))+('DCF Model'!L16*(1+0.02)/(0.12-0.02))/(1+0.12)^10-Assumptions!B48+Assumptions!B49)/Assumptions!B50 -> 133.75244
A7: 0.0275 | B7: =('DCF Model'!L31*((0.07/Assumptions!B40))+('DCF Model'!L16*(1+0.0275)/(0.07-0.0275))/(1+0.07)^10-Assumptions!B48+Assumptions!B49)/Assumptions!B50 -> 252.63929 | C7: =('DCF Model'!L31*((0.08/Assumptions!B40))+('DCF Model'!L16*(1+0.0275)/(0.08-0.0275))/(1+0.08)^10-Assumptions!B48+Assumptions!B49)/Assumptions!B50 -> 204.91724 | D7: =('DCF Model'!L31*((0.09/Assumptions!B40))+('DCF Model'!L16*(1+0.0275)/(0.09-0.0275))/(1+0.09)^10-Assumptions!B48+Assumptions!B49)/Assumptions!B50 -> 175.76182 | E7: =('DCF Model'!L31*((0.1/Assumptions!B40))+('DCF Model'!L16*(1+0.0275)/(0.1-0.0275))/(1+0.1)^10-Assumptions!B48+Assumptions!B49)/Assumptions!B50 -> 157.38112 | F7: =('DCF Model'!L31*((0.11/Assumptions!B40))+('DCF Model'!L16*(1+0.0275)/(0.11-0.0275))/(1+0.11)^10-Assumptions!B48+Assumptions!B49)/Assumptions!B50 -> 145.7719 | G7: =('DCF Model'!L31*((0.12/Assumptions!B40))+('DCF Model'!L16*(1+0.0275)/(0.12-0.0275))/(1+0.12)^10-Assumptions!B48+Assumptions!B49)/Assumptions!B50 -> 138.67053
A8: 0.03 | B8: =('DCF Model'!L31*((0.07/Assumptions!B40))+('DCF Model'!L16*(1+0.03)/(0.07-0.03))/(1+0.07)^10-Assumptions!B48+Assumptions!B49)/Assumptions!B50 -> 266.09405 | C8: =('DCF Model'!L31*((0.08/Assumptions!B40))+('DCF Model'!L16*(1+0.03)/(0.08-0.03))/(1+0.08)^10-Assumptions!B48+Assumptions!B49)/Assumptions!B50 -> 212.931 | D8: =('DCF Model'!L31*((0.09/Assumptions!B40))+('DCF Model'!L16*(1+0.03)/(0.09-0.03))/(1+0.09)^10-Assumptions!B48+Assumptions!B49)/Assumptions!B50 -> 180.92491 | E8: =('DCF Model'!L31*((0.1/Assumptions!B40))+('DCF Model'!L16*(1+0.03)/(0.1-0.03))/(1+0.1)^10-Assumptions!B48+Assumptions!B49)/Assumptions!B50 -> 160.89518 | F8: =('DCF Model'!L31*((0.11/Assumptions!B40))+('DCF Model'!L16*(1+0.03)/(0.11-0.03))/(1+0.11)^10-Assumptions!B48+Assumptions!B49)/Assumptions!B50 -> 148.26264 | G8: =('DCF Model'!L31*((0.12/Assumptions!B40))+('DCF Model'!L16*(1+0.03)/(0.12-0.03))/(1+0.12)^10-Assumptions!B48+Assumptions!B49)/Assumptions!B50 -> 140.49204
A9: 0.035 | B9: =('DCF Model'!L31*((0.07/Assumptions!B40))+('DCF Model'!L16*(1+0.035)/(0.07-0.035))/(1+0.07)^10-Assumptions!B48+Assumptions!B49)/Assumptions!B50 -> 298.76992 | C9: =('DCF Model'!L31*((0.08/Assumptions!B40))+('DCF Model'!L16*(1+0.035)/(0.08-0.035))/(1+0.08)^10-Assumptions!B48+Assumptions!B49)/Assumptions!B50 -> 231.62976 | D9: =('DCF Model'!L31*((0.09/Assumptions!B40))+('DCF Model'!L16*(1+0.035)/(0.09-0.035))/(1+0.09)^10-Assumptions!B48+Assumptions!B49)/Assumptions!B50 -> 192.6592 | E9: =('DCF Model'!L31*((0.1/Assumptions!B40))+('DCF Model'!L16*(1+0.035)/(0.1-0.035))/(1+0.1)^10-Assumptions!B48+Assumptions!B49)/Assumptions!B50 -> 168.73423 | F9: =('DCF Model'!L31*((0.11/Assumptions!B40))+('DCF Model'!L16*(1+0.035)/(0.11-0.035))/(1+0.11)^10-Assumptions!B48+Assumptions!B49)/Assumptions!B50 -> 153.74226 | G9: =('DCF Model'!L31*((0.12/Assumptions!B40))+('DCF Model'!L16*(1+0.035)/(0.12-0.035))/(1+0.12)^10-Assumptions!B48+Assumptions!B49)/Assumptions!B50 -> 144.45651
A11: Sensitivity Analysis — Implied Share Price (Exit Multiple)
A12: Implied Share Price by WACC & EV/EBIT Exit Multiple (10-Year Model)
A13: WACC → | B13: 18x | C13: 22x | D13: 26x | E13: 28x | F13: 32x | G13: 36x | H13: Mult ↓
A14: 0.07 | B14: =('DCF Model'!L31*((0.07/Assumptions!B40))+('DCF Model'!L10*18)/(1+0.07)^10-Assumptions!B48+Assumptions!B49)/Assumptions!B50 -> 236.73627 | C14: =('DCF Model'!L31*((0.07/Assumptions!B40))+('DCF Model'!L10*22)/(1+0.07)^10-Assumptions!B48+Assumptions!B49)/Assumptions!B50 -> 279.14129 | D14: =('DCF Model'!L31*((0.07/Assumptions!B40))+('DCF Model'!L10*26)/(1+0.07)^10-Assumptions!B48+Assumptions!B49)/Assumptions!B50 -> 321.5463 | E14: =('DCF Model'!L31*((0.07/Assumptions!B40))+('DCF Model'!L10*28)/(1+0.07)^10-Assumptions!B48+Assumptions!B49)/Assumptions!B50 -> 342.74881 | F14: =('DCF Model'!L31*((0.07/Assumptions!B40))+('DCF Model'!L10*32)/(1+0.07)^10-Assumptions!B48+Assumptions!B49)/Assumptions!B50 -> 385.15382 | G14: =('DCF Model'!L31*((0.07/Assumptions!B40))+('DCF Model'!L10*36)/(1+0.07)^10-Assumptions!B48+Assumptions!B49)/Assumptions!B50 -> 427.55884
A15: 0.08 | B15: =('DCF Model'!L31*((0.08/Assumptions!B40))+('DCF Model'!L10*18)/(1+0.08)^10-Assumptions!B48+Assumptions!B49)/Assumptions!B50 -> 226.30544 | C15: =('DCF Model'!L31*((0.08/Assumptions!B40))+('DCF Model'!L10*22)/(1+0.08)^10-Assumptions!B48+Assumptions!B49)/Assumptions!B50 -> 264.94369 | D15: =('DCF Model'!L31*((0.08/Assumptions!B40))+('DCF Model'!L10*26)/(1+0.08)^10-Assumptions!B48+Assumptions!B49)/Assumptions!B50 -> 303.58194 | E15: =('DCF Model'!L31*((0.08/Assumptions!B40))+('DCF Model'!L10*28)/(1+0.08)^10-Assumptions!B48+Assumptions!B49)/Assumptions!B50 -> 322.90106 | F15: =('DCF Model'!L31*((0.08/Assumptions!B40))+('DCF Model'!L10*32)/(1+0.08)^10-Assumptions!B48+Assumptions!B49)/Assumptions!B50 -> 361.53931 | G15: =('DCF Model'!L31*((0.08/Assumptions!B40))+('DCF Model'!L10*36)/(1+0.08)^10-Assumptions!B48+Assumptions!B49)/Assumptions!B50 -> 400.17756
A16: 0.09 | B16: =('DCF Model'!L31*((0.09/Assumptions!B40))+('DCF Model'!L10*18)/(1+0.09)^10-Assumptions!B48+Assumptions!B49)/Assumptions!B50 -> 217.51617 | C16: =('DCF Model'!L31*((0.09/Assumptions!B40))+('DCF Model'!L10*22)/(1+0.09)^10-Assumptions!B48+Assumptions!B49)/Assumptions!B50 -> 252.75245 | D16: =('DCF Model'!L31*((0.09/Assumptions!B40))+('DCF Model'!L10*26)/(1+0.09)^10-Assumptions!B48+Assumptions!B49)/Assumptions!B50 -> 287.98873 | E16: =('DCF Model'!L31*((0.09/Assumptions!B40))+('DCF Model'!L10*28)/(1+0.09)^10-Assumptions!B48+Assumptions!B49)/Assumptions!B50 -> 305.60686 | F16: =('DCF Model'!L31*((0.09/Assumptions!B40))+('DCF Model'!L10*32)/(1+0.09)^10-Assumptions!B48+Assumptions!B49)/Assumptions!B50 -> 340.84314 | G16: =('DCF Model'!L31*((0.09/Assumptions!B40))+('DCF Model'!L10*36)/(1+0.09)^10-Assumptions!B48+Assumptions!B49)/Assumptions!B50 -> 376.07942
A17: 0.1 | B17: =('DCF Model'!L31*((0.1/Assumptions!B40))+('DCF Model'!L10*18)/(1+0.1)^10-Assumptions!B48+Assumptions!B49)/Assumptions!B50 -> 210.19657 | C17: =('DCF Model'!L31*((0.1/Assumptions!B40))+('DCF Model'!L10*22)/(1+0.1)^10-Assumptions!B48+Assumptions!B49)/Assumptions!B50 -> 242.35746 | D17: =('DCF Model'!L31*((0.1/Assumptions!B40))+('DCF Model'!L10*26)/(1+0.1)^10-Assumptions!B48+Assumptions!B49)/Assumptions!B50 -> 274.51836 | E17: =('DCF Model'!L31*((0.1/Assumptions!B40))+('DCF Model'!L10*28)/(1+0.1)^10-Assumptions!B48+Assumptions!B49)/Assumptions!B50 -> 290.59881 | F17: =('DCF Model'!L31*((0.1/Assumptions!B40))+('DCF Model'!L10*32)/(1+0.1)^10-Assumptions!B48+Assumptions!B49)/Assumptions!B50 -> 322.7597 | G17: =('DCF Model'!L31*((0.1/Assumptions!B40))+('DCF Model'!L10*36)/(1+0.1)^10-Assumptions!B48+Assumptions!B49)/Assumptions!B50 -> 354.9206
A18: 0.11 | B18: =('DCF Model'!L31*((0.11/Assumptions!B40))+('DCF Model'!L10*18)/(1+0.11)^10-Assumptions!B48+Assumptions!B49)/Assumptions!B50 -> 204.19405 | C18: =('DCF Model'!L31*((0.11/Assumptions!B40))+('DCF Model'!L10*22)/(1+0.11)^10-Assumptions!B48+Assumptions!B49)/Assumptions!B50 -> 233.57225 | D18: =('DCF Model'!L31*((0.11/Assumptions!B40))+('DCF Model'!L10*26)/(1+0.11)^10-Assumptions!B48+Assumptions!B49)/Assumptions!B50 -> 262.95045 | E18: =('DCF Model'!L31*((0.11/Assumptions!B40))+('DCF Model'!L10*28)/(1+0.11)^10-Assumptions!B48+Assumptions!B49)/Assumptions!B50 -> 277.63956 | F18: =('DCF Model'!L31*((0.11/Assumptions!B40))+('DCF Model'!L10*32)/(1+0.11)^10-Assumptions!B48+Assumptions!B49)/Assumptions!B50 -> 307.01776 | G18: =('DCF Model'!L31*((0.11/Assumptions!B40))+('DCF Model'!L10*36)/(1+0.11)^10-Assumptions!B48+Assumptions!B49)/Assumptions!B50 -> 336.39596
A19: 0.12 | B19: =('DCF Model'!L31*((0.12/Assumptions!B40))+('DCF Model'!L10*18)/(1+0.12)^10-Assumptions!B48+Assumptions!B49)/Assumptions!B50 -> 199.37306 | C19: =('DCF Model'!L31*((0.12/Assumptions!B40))+('DCF Model'!L10*22)/(1+0.12)^10-Assumptions!B48+Assumptions!B49)/Assumptions!B50 -> 226.23113 | D19: =('DCF Model'!L31*((0.12/Assumptions!B40))+('DCF Model'!L10*26)/(1+0.12)^10-Assumptions!B48+Assumptions!B49)/Assumptions!B50 -> 253.0892 | E19: =('DCF Model'!L31*((0.12/Assumptions!B40))+('DCF Model'!L10*28)/(1+0.12)^10-Assumptions!B48+Assumptions!B49)/Assumptions!B50 -> 266.51823 | F19: =('DCF Model'!L31*((0.12/Assumptions!B40))+('DCF Model'!L10*32)/(1+0.12)^10-Assumptions!B48+Assumptions!B49)/Assumptions!B50 -> 293.3763 | G19: =('DCF Model'!L31*((0.12/Assumptions!B40))+('DCF Model'!L10*36)/(1+0.12)^10-Assumptions!B48+Assumptions!B49)/Assumptions!B50 -> 320.23437

Sheet EV-EBITDA Comps
A1: EV / EBITDA COMPARABLE COMPANY ANALYSIS
A2: NVIDIA Corporation (NVDA) | Equity Research Valuation Model
A3: Color Legend: | B3: Blue = Input | C3: Black = Formula
A5: SUBJECT COMPANY INPUTS
A6: Subject Company Name | D6: NVIDIA Corporation (NVDA)
A7: NTM EBITDA ($M) | B7: 232000 | D7: 232000
A8: Applied Multiple Premium/Disc | B8: 0.15 | D8: Premium (+) or discount (-) to peer median
A9: Net Debt / (Cash) ($M) | B9: -6768 | D9: -6768
A10: Shares Outstanding (M) | B10: 24483 | D10: 24483
A11: Current Stock Price ($) | B11: 181.69 | D11: 181.69
A13: PEER GROUP
A14: Company | B14: Ticker | C14: Market Cap ($M) | D14: Net Debt ($M) | E14: EV ($M) | F14: NTM Revenue ($M) | G14: NTM EBITDA ($M) | H14: EV/Revenue (NTM) | I14: EV/EBITDA (NTM) | J14: NTM EBITDA Margin | K14: Notes
A15: Broadcom Inc. | B15: AVGO | C15: 1570000 | D15: 67000 | E15: =C15+D15 -> 1637000 | F15: 82000 | G15: 43000 | H15: =IF(F15>0,E15/F15,"-") -> 19.963415 | I15: =IF(G15>0,E15/G15,"-") -> 38.069767 | J15: =IF(F15>0,G15/F15,"-") -> 0.52439024 | K15: AI custom silicon + VMware software; EV/EBITDA ~44x TTM
A16: Taiwan Semiconductor Mfg. | B16: TSM | C16: 1760000 | D16: -60000 | E16: =C16+D16 -> 1700000 | F16: 135000 | G16: 97000 | H16: =IF(F16>0,E16/F16,"-") -> 12.592593 | I16: =IF(G16>0,E16/G16,"-") -> 17.525773 | J16: =IF(F16>0,G16/F16,"-") -> 0.71851852 | K16: World largest foundry; NVDA primary fab partner; 72% EBITDA margin
A17: Advanced Micro Devices | B17: AMD | C17: 320000 | D17: 2000 | E17: =C17+D17 -> 322000 | F17: 32000 | G17: 8500 | H17: =IF(F17>0,E17/F17,"-") -> 10.0625 | I17: =IF(G17>0,E17/G17,"-") -> 37.882353 | J17: =IF(F17>0,G17/F17,"-") -> 0.265625 | K17: Primary GPU competitor; data center growing 22% YoY
A18: Marvell Technology | B18: MRVL | C18: 80000 | D18: 2500 | E18: =C18+D18 -> 82500 | F18: 7500 | G18: 2800 | H18: =IF(F18>0,E18/F18,"-") -> 11 | I18: =IF(G18>0,E18/G18,"-") -> 29.464286 | J18: =IF(F18>0,G18/F18,"-") -> 0.37333333 | K18: Custom AI ASIC for hyperscalers; high-growth emerging peer
A19: Qualcomm Inc. | B19: QCOM | C19: 160000 | D19: 6000 | E19: =C19+D19 -> 166000 | F19: 44000 | G19: 14000 | H19: =IF(F19>0,E19/F19,"-") -> 3.7727273 | I19: =IF(G19>0,E19/G19,"-") -> 11.857143 | J19: =IF(F19>0,G19/F19,"-") -> 0.31818182 | K19: Diversified semi; mobile/edge AI; lower growth vs AI peers
A20: Intel Corporation | B20: INTC | C20: 90000 | D20: 18000 | E20: =C20+D20 -> 108000 | F20: 55000 | G20: 9000 | H20: =IF(F20>0,E20/F20,"-") -> 1.9636364 | I20: =IF(G20>0,E20/G20,"-") -> 12 | J20: =IF(F20>0,G20/F20,"-") -> 0.16363636 | K20: Turnaround story; foundry + legacy CPU; structurally challenged
A21: Peer Mean | H21: =IFERROR(AVERAGE(H15:H20),"-") -> 9.8924785 | I21: =IFERROR(AVERAGE(I15:I20),"-") -> 24.466554
A22: Peer Median | H22: =IFERROR(AVERAGE(H16:H20),"-") -> 7.8782912 | I22: =IFERROR(MEDIAN(I15:I20),"-") -> 23.495029
A23: Peer High | H23: =IFERROR(AVERAGE(H17:H20),"-") -> 6.6997159 | I23: =IFERROR(MEDIAN(I16:I21),"-") -> 20.996163
A24: Peer Low | H24: =IFERROR(AVERAGE(H18:H21),"-") -> 6.6572105 | I24: =IFERROR(MEDIAN(I17:I22),"-") -> 23.980792
A28: VALUATION OUTPUT
A29: Peer Median EV/EBITDA | B29: =IFERROR(MEDIAN(I15:I20),0) -> 23.495029
A30: Applied Premium / (Discount) | B30: =$B$8 -> 0.15
A31: Applied EV/EBITDA Multiple | B31: =B29*(1+B30) -> 27.019284
A32: NTM EBITDA ($M) | B32: =$B$7 -> 232000
A33: Implied Enterprise Value ($M) | B33: =B31*B32 -> 6268473.9
A34: Less: Net Debt ($M) | B34: =$B$9 -> -6768
A35: Implied Equity Value ($M) | B35: =B33-B34 -> 6275241.9
A36: Shares Outstanding (M) | B36: =$B$10 -> 24483
A37: Implied Share Price ($) | B37: =IF(B36>0,B35/B36,"N/A") -> 256.31017
A38: Current Stock Price ($) | B38: =$B$11 -> 181.69
A39: Implied Upside / (Downside) | B39: =IF(ISNUMBER(B37),(B37-B38)/B38,"N/A") -> 0.41070047
A42: SENSITIVITY — Implied Price vs. EV/EBITDA Multiple & EBITDA
A43: Implied Share Price ($) — rows = applied EV/EBITDA multiple, cols = NTM EBITDA ($M)
A44: Multiple → / EBITDA % chg ↓ | B44: -20% | C44: -10% | D44: +0% | E44: +10% | F44: +20%
A45: 20 | B45: =IF(AND(ISNUMBER($B$7),$B$10>0),(8*$B$7*(1+-0.2)-$B$9)/$B$10,"N/A") -> 60.922599 | C45: =IF(AND(ISNUMBER($B$7),$B$10>0),(8*$B$7*(1+-0.1)-$B$9)/$B$10,"N/A") -> 68.50337 | D45: =IF(AND(ISNUMBER($B$7),$B$10>0),(8*$B$7*(1+0)-$B$9)/$B$10,"N/A") -> 76.08414 | E45: =IF(AND(ISNUMBER($B$7),$B$10>0),(8*$B$7*(1+0.1)-$B$9)/$B$10,"N/A") -> 83.66491 | F45: =IF(AND(ISNUMBER($B$7),$B$10>0),(8*$B$7*(1+0.2)-$B$9)/$B$10,"N/A") -> 91.245681
A46: 25 | B46: =IF(AND(ISNUMBER($B$7),$B$10>0),(10*$B$7*(1+-0.2)-$B$9)/$B$10,"N/A") -> 76.08414 | C46: =IF(AND(ISNUMBER($B$7),$B$10>0),(10*$B$7*(1+-0.1)-$B$9)/$B$10,"N/A") -> 85.560103 | D46: =IF(AND(ISNUMBER($B$7),$B$10>0),(10*$B$7*(1+0)-$B$9)/$B$10,"N/A") -> 95.036066 | E46: =IF(AND(ISNUMBER($B$7),$B$10>0),(10*$B$7*(1+0.1)-$B$9)/$B$10,"N/A") -> 104.51203 | F46: =IF(AND(ISNUMBER($B$7),$B$10>0),(10*$B$7*(1+0.2)-$B$9)/$B$10,"N/A") -> 113.98799
A47: 30 | B47: =IF(AND(ISNUMBER($B$7),$B$10>0),(12*$B$7*(1+-0.2)-$B$9)/$B$10,"N/A") -> 91.245681 | C47: =IF(AND(ISNUMBER($B$7),$B$10>0),(12*$B$7*(1+-0.1)-$B$9)/$B$10,"N/A") -> 102.61684 | D47: =IF(AND(ISNUMBER($B$7),$B$10>0),(12*$B$7*(1+0)-$B$9)/$B$10,"N/A") -> 113.98799 | E47: =IF(AND(ISNUMBER($B$7),$B$10>0),(12*$B$7*(1+0.1)-$B$9)/$B$10,"N/A") -> 125.35915 | F47: =IF(AND(ISNUMBER($B$7),$B$10>0),(12*$B$7*(1+0.2)-$B$9)/$B$10,"N/A") -> 136.7303
...

Sheet PE Comps
A1: P / E COMPARABLE COMPANY ANALYSIS
A2: NVIDIA Corporation (NVDA) | Equity Research Valuation Model
A3: Color Legend: | B3: Blue = Input | C3: Black = Formula
A5: SUBJECT COMPANY INPUTS
A6: Subject Company Name | B6: NVIDIA Corporation (NVDA)
A7: NTM EPS ($) | B7: 8.3
A8: Applied Multiple Premium/Disc | B8: 0.2 | D8: Premium (+) or discount (-) to peer median
A9: Current Stock Price ($) | B9: 181.69
A11: PEER GROUP
A12: Company | B12: Ticker | C12: Stock Price ($) | D12: NTM EPS ($) | E12: P/E (NTM) | F12: EPS Growth (NTM) | G12: PEG Ratio | H12: Dividend Yield | I12: Net Margin | J12: Notes
A13: Broadcom Inc. | B13: AVGO | C13: 330 | D13: 13.32 | E13: =IF(D13>0,C13/D13,"-") -> 24.774775 | F13: 0.35 | G13: =IF(AND(E13<>"-",F13>0),E13/(F13*100),"-") -> 0.70785071 | H13: 0.008 | I13: 0.362 | J13: Fwd P/E ~25x; AI custom chip + software mix
A14: Taiwan Semiconductor Mfg. | B14: TSM | C14: 353.86 | D14: 10.6 | E14: =IF(D14>0,C14/D14,"-") -> 33.383019 | F14: 0.3 | G14: =IF(AND(E14<>"-",F14>0),E14/(F14*100),"-") -> 1.1127673 | H14: 0.011 | I14: 0.4 | J14: Fwd P/E ~33x; foundry premium; 30% EPS growth
A15: Advanced Micro Devices | B15: AMD | C15: 99 | D15: 4.2 | E15: =IF(D15>0,C15/D15,"-") -> 23.571429 | F15: 0.25 | G15: =IF(AND(E15<>"-",F15>0),E15/(F15*100),"-") -> 0.94285714 | H15: 0 | I15: 0.068 | J15: Fwd P/E ~24x; turnaround in data center GPU
A16: Marvell Technology | B16: MRVL | C16: 65 | D16: 3.1 | E16: =IF(D16>0,C16/D16,"-") -> 20.967742 | F16: 0.45 | G16: =IF(AND(E16<>"-",F16>0),E16/(F16*100),"-") -> 0.46594982 | H16: 0.004 | I16: 0.082 | J16: High growth custom ASIC; expanding margins
A17: Qualcomm Inc. | B17: QCOM | C17: 145 | D17: 11.5 | E17: =IF(D17>0,C17/D17,"-") -> 12.608696 | F17: 0.08 | G17: =IF(AND(E17<>"-",F17>0),E17/(F17*100),"-") -> 1.576087 | H17: 0.022 | I17: 0.272 | J17: Lower growth; diversified mobile + auto + IoT
A18: Intel Corporation | B18: INTC | C18: 22 | D18: 0.55 | E18: =IF(D18>0,C18/D18,"-") -> 40 | F18: 0.5 | G18: =IF(AND(E18<>"-",F18>0),E18/(F18*100),"-") -> 0.8 | H18: 0 | I18: 0.015 | J18: Deep turnaround; EPS recovering from near zero
A19: Peer Mean | E19: =IFERROR(AVERAGE(E13:E18),"-") -> 25.884277 | G19: =IFERROR(AVERAGE(G13:G18),"-") -> 0.93425199
A20: Peer Median | E20: =IFERROR(MEDIAN(E13:E18),"-") -> 24.173102 | G20: =IFERROR(MEDIAN(G13:G18),"-") -> 0.87142857
A21: Peer High | E21: =IFERROR(MAX(E13:E18),"-") -> 40 | G21: =IFERROR(MAX(G13:G18),"-") -> 1.576087
A22: Peer Low | E22: =IFERROR(MIN(E13:E18),"-") -> 12.608696 | G22: =IFERROR(MIN(G13:G18),"-") -> 0.46594982
A26: VALUATION OUTPUT
A27: Peer Median P/E (NTM) | B27: =IFERROR(MEDIAN(E13:E18),0) -> 24.173102
A28: Applied Premium / (Discount) | B28: =$B$8 -> 0.2
A29: Applied P/E Multiple | B29: =B27*(1+B28) -> 29.007722
A30: NTM EPS ($) | B30: =$B$7 -> 8.3
A31: Implied Share Price ($) | B31: =IF(AND(ISNUMBER(B30),B30>0),B29*B30,"N/A") -> 240.76409
A32: Current Stock Price ($) | B32: =$B$9 -> 181.69
A33: Implied Upside / (Downside) | B33: =IF(ISNUMBER(B31),(B31-B32)/B32,"N/A") -> 0.32513673
A36: SENSITIVITY — Implied Price vs. P/E Multiple & NTM EPS
A37: Implied Share Price ($) — rows = applied P/E multiple, cols = NTM EPS variation
A38: P/E → / EPS % chg ↓ | B38: -20% | C38: -10% | D38: +0% | E38: +10% | F38: +20%
A39: 20 | B39: =IF(ISNUMBER($B$7),10*$B$7*(1+-0.2),"N/A") -> 66.4 | C39: =IF(ISNUMBER($B$7),10*$B$7*(1+-0.1),"N/A") -> 74.7 | D39: =IF(ISNUMBER($B$7),10*$B$7*(1+0),"N/A") -> 83 | E39: =IF(ISNUMBER($B$7),10*$B$7*(1+0.1),"N/A") -> 91.3 | F39: =IF(ISNUMBER($B$7),10*$B$7*(1+0.2),"N/A") -> 99.6
A40: 25 | B40: =IF(ISNUMBER($B$7),15*$B$7*(1+-0.2),"N/A") -> 99.6 | C40: =IF(ISNUMBER($B$7),15*$B$7*(1+-0.1),"N/A") -> 112.05 | D40: =IF(ISNUMBER($B$7),15*$B$7*(1+0),"N/A") -> 124.5 | E40: =IF(ISNUMBER($B$7),15*$B$7*(1+0.1),"N/A") -> 136.95 | F40: =IF(ISNUMBER($B$7),15*$B$7*(1+0.2),"N/A") -> 149.4
A41: 30 | B41: =IF(ISNUMBER($B$7),20*$B$7*(1+-0.2),"N/A") -> 132.8 | C41: =IF(ISNUMBER($B$7),20*$B$7*(1+-0.1),"N/A") -> 149.4 | D41: =IF(ISNUMBER($B$7),20*$B$7*(1+0),"N/A") -> 166 | E41: =IF(ISNUMBER($B$7),20*$B$7*(1+0.1),"N/A") -> 182.6 | F41: =IF(ISNUMBER($B$7),20*$B$7*(1+0.2),"N/A") -> 199.2
A42: 35 | B42: =IF(ISNUMBER($B$7),25*$B$7*(1+-0.2),"N/A") -> 166 | C42: =IF(ISNUMBER($B$7),25*$B$7*(1+-0.1),"N/A") -> 186.75 | D42: =IF(ISNUMBER($B$7),25*$B$7*(1+0),"N/A") -> 207.5 | E42: =IF(ISNUMBER($B$7),25*$B$7*(1+0.1),"N/A") -> 228.25 | F42: =IF(ISNUMBER($B$7),25*$B$7*(1+0.2),"N/A") -> 249
A43: 40 | B43: =IF(ISNUMBER($B$7),30*$B$7*(1+-0.2),"N/A") -> 199.2 | C43: =IF(ISNUMBER($B$7),30*$B$7*(1+-0.1),"N/A") -> 224.1 | D43: =IF(ISNUMBER($B$7),30*$B$7*(1+0),"N/A") -> 249 | E43: =IF(ISNUMBER($B$7),30*$B$7*(1+0.1),"N/A") -> 273.9 | F43: =IF(ISNUMBER($B$7),30*$B$7*(1+0.2),"N/A") -> 298.8
A44: 45 | B44: =IF(ISNUMBER($B$7),35*$B$7*(1+-0.2),"N/A") -> 232.4 | C44: =IF(ISNUMBER($B$7),35*$B$7*(1+-0.1),"N/A") -> 261.45 | D44: =IF(ISNUMBER($B$7),35*$B$7*(1+0),"N/A") -> 290.5 | E44: =IF(ISNUMBER($B$7),35*$B$7*(1+0.1),"N/A") -> 319.55 | F44: =IF(ISNUMBER($B$7),35*$B$7*(1+0.2),"N/A") -> 348.6
A45: 50 | B45: =IF(ISNUMBER($B$7),40*$B$7*(1+-0.2),"N/A") -> 265.6 | C45: =IF(ISNUMBER($B$7),40*$B$7*(1+-0.1),"N/A") -> 298.8 | D45: =IF(ISNUMBER($B$7),40*$B$7*(1+0),"N/A") -> 332 | E45: =IF(ISNUMBER($B$7),40*$B$7*(1+0.1),"N/A") -> 365.2 | F45: =IF(ISNUMBER($B$7),40*$B$7*(1+0.2),"N/A") -> 398.4

Sheet Valuation Summary
A1: VALUATION SUMMARY — BLENDED PRICE TARGET
A2: NVIDIA Corporation (NVDA) | Equity Research Valuation Model
A4: BLENDED PRICE TARGET BRIDGE
A5: Valuation Method | B5: Implied Price ($) | C5: Weighting | D5: Weighted Value ($) | E5: Notes
A6: DCF | B6: 220 | C6: 0.334 | D6: =IF(ISNUMBER(B6),B6*C6,0) -> 73.48 | E6: DCF midpoint: GG 55 / Exit Multiple 85; blended ~20 (see NVDA_DCF_v2.xlsx)
A7: EV/EBITDA Comps | B7: ='EV-EBITDA Comps'!B37 -> 256.31017 | C7: 0.333 | D7: =IF(ISNUMBER(B7),B7*C7,0) -> 85.351286 | E7: Based on NTM EBITDA 32B and peer median EV/EBITDA applied with 15% AI premium
A8: P/E Comps | B8: ='PE Comps'!B31 -> 240.76409 | C8: 0.333 | D8: =IF(ISNUMBER(B8),B8*C8,0) -> 80.174443 | E8: Based on NTM EPS .30 and peer median P/E applied with 20% AI leadership premium
A9: Weight Check (must = 100%) | C9: =SUM(C6:C8) -> 1
A10: BLENDED PRICE TARGET ($) | D10: =IF(C9=1,SUM(D6:D8),"Check weights!") -> 239.00573
A12: UPSIDE / (DOWNSIDE) SUMMARY
A13: Current Stock Price ($) | B13: 181.69
A14: Blended Price Target ($) | B14: =D10 -> 239.00573
A15: Implied Upside / (Downside) | B15: =IF(ISNUMBER(D10),(D10-B13)/B13,"N/A") -> 0.31545891
A16: Rating | B16: BUY
